<?xml version="1.0" ?>
<!-- =================================================================================== -->
<!-- |    This document was autogenerated by xacro from /home/lll/ros_ws/src/bmirobot_pkg/bmirobot_description/urdf/robotarm_description.xacro | -->
<!-- |    EDITING THIS FILE BY HAND IS NOT RECOMMENDED                                 | -->
<!-- =================================================================================== -->
<robot name="robotarm">
    <!-- Space btw top of beam and the each joint -->
    <material name="black">
        <color rgba="0.0 0.0 0.0 1.0" />
    </material>
    <material name="blue">
        <color rgba="0.0 0.0 0.8 1.0" />
    </material>
    <material name="green">
        <color rgba="0.0 0.8 0.0 1.0" />
    </material>
    <material name="grey">
        <color rgba="0.2 0.2 0.2 1.0" />
    </material>
    <material name="orange">
        <color rgba="1.0 0.4235294117647059 0.0392156862745098 1.0" />
    </material>
    <material name="brown">
        <color rgba="0.8705882352941177 0.8117647058823529 0.7647058823529411 1.0" />
    </material>
    <material name="red">
        <color rgba="0.8 0.0 0.0 1.0" />
    </material>
    <material name="white">
        <color rgba="1.0 1.0 1.0 1.0" />
    </material>
    <!-- Used for fixing robot to Gazebo 'base_link' -->
    <link name="world" />
    <joint name="fixed" type="fixed">
        <parent link="world" />
        <child link="odom_combined" />
    </joint>
    <link name="odom_combined" />
    <joint name="virtual_joint" type="fixed">
        <parent link="odom_combined" />
        <child link="base_link" />
        <origin rpy="0 0 0" xyz="0 0 0.45" />
    </joint>
    <link name="base_link" />
    <joint name="rightvirtual_joint" type="fixed">
        <parent link="base_link" />
        <child link="right_link1" />
        <origin rpy="0 0 -1.5707963267948966" xyz="0 -0.22 0" />
    </joint>
    <joint name="leftvirtual_joint" type="fixed">
        <parent link="base_link" />
        <child link="left_link1" />
        <origin rpy="0 0 1.5707963267948966" xyz="0 0.22 0 " />
    </joint>
    <link name="right_link1">
        <visual>
            <geometry>
                <mesh filename="package://bmirobot_description/modle/stl_V5/baselink.dae" />
            </geometry>
            <origin rpy="0 0 0" xyz="0 0 0" />
            <material name="red" />
        </visual>
        <collision>
            <geometry>
                <mesh filename="package://bmirobot_description/modle/stl_V5/baselink.dae" />
            </geometry>
            <origin rpy="0 0 0" xyz="0 0 0" />
        </collision>
        <inertial>
            <origin rpy="0 0 0" xyz="0 0 1" />
            <mass value="1" />
            <inertia ixx="1.0" ixy="0.0" ixz="0.0" iyy="1.0" iyz="0.0" izz="1.0" />
        </inertial>
    </link>
    <link name="right_link2">
        <visual>
            <geometry>
                <mesh filename="package://bmirobot_description/modle/stl_V5/link1.dae" />
            </geometry>
            <origin rpy="0 0 0" xyz="0 0 0" />
            <material name="white" />
        </visual>
        <collision>
            <geometry>
                <mesh filename="package://bmirobot_description/modle/stl_V5/link1.dae" />
            </geometry>
            <origin rpy="0 0 0" xyz="0 0 0" />
        </collision>
        <inertial>
            <origin rpy="0 0 0" xyz="0 0 1" />
            <mass value="1" />
            <inertia ixx="1.0" ixy="0.0" ixz="0.0" iyy="1.0" iyz="0.0" izz="1.0" />
        </inertial>
    </link>
    <link name="right_link3">
        <visual>
            <geometry>
                <mesh filename="package://bmirobot_description/modle/stl_V5/link2.dae" />
            </geometry>
            <origin rpy="0 0 0" xyz="0 0 0" />
            <material name="blue" />
        </visual>
        <collision>
            <geometry>
                <mesh filename="package://bmirobot_description/modle/stl_V5/link2.dae" />
            </geometry>
            <origin rpy="0 0 0" xyz="0 0 0" />
        </collision>
        <inertial>
            <origin rpy="0 0 0" xyz="0 0 1" />
            <mass value="1" />
            <inertia ixx="1.0" ixy="0.0" ixz="0.0" iyy="1.0" iyz="0.0" izz="1.0" />
        </inertial>
    </link>
    <link name="right_link4">
        <visual>
            <geometry>
                <mesh filename="package://bmirobot_description/modle/stl_V5/link3.dae" />
            </geometry>
            <origin rpy="0 0 0" xyz="0 0 0" />
            <material name="orange" />
        </visual>
        <collision>
            <geometry>
                <mesh filename="package://bmirobot_description/modle/stl_V5/link3.dae" />
            </geometry>
            <origin rpy="0 0 0" xyz="0 0 0" />
        </collision>
        <inertial>
            <origin rpy="0 0 0" xyz="0 0 1" />
            <mass value="1" />
            <inertia ixx="1.0" ixy="0.0" ixz="0.0" iyy="1.0" iyz="0.0" izz="1.0" />
        </inertial>
    </link>
    <link name="right_link5">
        <visual>
            <geometry>
                <mesh filename="package://bmirobot_description/modle/stl_V5/link4.dae" />
            </geometry>
            <origin rpy="0 0 0" xyz="0 0 0" />
            <material name="blue" />
        </visual>
        <collision>
            <geometry>
                <mesh filename="package://bmirobot_description/modle/stl_V5/link4.dae" />
            </geometry>
            <origin rpy="0 0 0" xyz="0 0 0" />
        </collision>
        <inertial>
            <origin rpy="0 0 0" xyz="0 0 1" />
            <mass value="1" />
            <inertia ixx="1.0" ixy="0.0" ixz="0.0" iyy="1.0" iyz="0.0" izz="1.0" />
        </inertial>
    </link>
    <link name="right_link6">
        <visual>
            <geometry>
                <mesh filename="package://bmirobot_description/modle/stl_V5/link5.dae" />
            </geometry>
            <origin rpy="0 0 0" xyz="0 0 0" />
            <material name="orange" />
        </visual>
        <collision>
            <geometry>
                <mesh filename="package://bmirobot_description/modle/stl_V5/link5.dae" />
            </geometry>
            <origin rpy="0 0 0" xyz="0 0 0" />
        </collision>
        <inertial>
            <origin rpy="0 0 0" xyz="0 0 1" />
            <mass value="1" />
            <inertia ixx="1.0" ixy="0.0" ixz="0.0" iyy="1.0" iyz="0.0" izz="1.0" />
        </inertial>
    </link>
    <link name="right_link7">
        <visual>
            <geometry>
                <mesh filename="package://bmirobot_description/modle/stl_V5/link6.dae" />
            </geometry>
            <origin rpy="0 0 0" xyz="0 0 0" />
            <material name="blue" />
        </visual>
        <collision>
            <geometry>
                <mesh filename="package://bmirobot_description/modle/stl_V5/link6.dae" />
            </geometry>
            <origin rpy="0 0 0" xyz="0 0 0" />
        </collision>
        <inertial>
            <origin rpy="0 0 0" xyz="0 0 1" />
            <mass value="1" />
            <inertia ixx="1.0" ixy="0.0" ixz="0.0" iyy="1.0" iyz="0.0" izz="1.0" />
        </inertial>
    </link>
    <link name="right_link8">
        <visual>
            <geometry>
                <mesh filename="package://bmirobot_description/modle/stl_V5/link7.dae" />
            </geometry>
            <origin rpy="0 0 0" xyz="0 0 0" />
            <material name="red" />
        </visual>
        <collision>
            <geometry>
                <mesh filename="package://bmirobot_description/modle/stl_V5/link7.dae" />
            </geometry>
            <origin rpy="0 0 0" xyz="0 0 0" />
        </collision>
        <inertial>
            <origin rpy="0 0 0" xyz="0 0 1" />
            <mass value="1" />
            <inertia ixx="1.0" ixy="0.0" ixz="0.0" iyy="1.0" iyz="0.0" izz="1.0" />
        </inertial>
    </link>
    <link name="right_hand1">
        <visual>
            <geometry>
                <mesh filename="package://bmirobot_description/modle/stl_V5/hand-1.dae" />
            </geometry>
            <origin rpy="0 0 0" xyz="0 0 0" />
            <material name="white" />
        </visual>
        <collision>
            <geometry>
                <mesh filename="package://bmirobot_description/modle/stl_V5/hand-1.dae" />
            </geometry>
            <origin rpy="0 0 0" xyz="0 0 0" />
        </collision>
        <inertial>
            <origin rpy="0 0 0" xyz="0 0 1" />
            <mass value="1" />
            <inertia ixx="1.0" ixy="0.0" ixz="0.0" iyy="1.0" iyz="0.0" izz="1.0" />
        </inertial>
    </link>
    <link name="right_hand2">
        <visual>
            <geometry>
                <mesh filename="package://bmirobot_description/modle/stl_V5/hand-2.dae" />
            </geometry>
            <origin rpy="0 0 0" xyz="0 0 0" />
            <material name="white" />
        </visual>
        <collision>
            <geometry>
                <mesh filename="package://bmirobot_description/modle/stl_V5/hand-2.dae" />
            </geometry>
            <origin rpy="0 0 0" xyz="0 0 0" />
        </collision>
        <inertial>
            <origin rpy="0 0 0" xyz="0 0 1" />
            <mass value="1" />
            <inertia ixx="1.0" ixy="0.0" ixz="0.0" iyy="1.0" iyz="0.0" izz="1.0" />
        </inertial>
    </link>
    <joint name="right_joint1" type="revolute">
        <limit effort="1000.0" lower="-1.5707963267948966" upper="3.141592653589793" velocity="9.42477796076938" />
        <origin rpy="0 0 0" xyz="0.081 0 0" />
        <axis xyz="1 0 0" />
        <parent link="right_link1" />
        <child link="right_link2" />
        <dynamics damping="0.7" />
    </joint>
    <joint name="right_joint2" type="revolute">
        <limit effort="1000.0" lower="-3.141592653589793" upper="0.17453292519943295" velocity="9.42477796076938" />
        <origin rpy="0 1.5707963267948966 0" xyz="0.040 0 0" />
        <axis xyz="0 1 0" />
        <parent link="right_link2" />
        <child link="right_link3" />
        <dynamics damping="0.7" />
    </joint>
    <joint name="right_joint3" type="revolute">
        <limit effort="1000.0" lower="-1.5707963267948966" upper="1.5707963267948966" velocity="9.42477796076938" />
        <origin rpy="-1.5707963267948966 0 0" xyz="0.0555 0 0" />
        <axis xyz="1 0 0" />
        <parent link="right_link3" />
        <child link="right_link4" />
        <dynamics damping="0.7" />
    </joint>
    <joint name="right_joint4" type="revolute">
        <limit effort="1000.0" lower="-0.8726646259971648" upper="2.0943951023931953" velocity="9.42477796076938" />
        <origin rpy="0 -1.5707963267948966 0" xyz="0.1945 0 0" />
        <axis xyz="0 1 0" />
        <parent link="right_link4" />
        <child link="right_link5" />
        <dynamics damping="0.7" />
    </joint>
    <joint name="right_joint5" type="revolute">
        <limit effort="1000.0" lower="-3.141592653589793" upper="1.7453292519943295" velocity="9.42477796076938" />
        <origin rpy="1.5707963267948966 0 0" xyz="0.037 0 0.000" />
        <axis xyz="1 0 0" />
        <parent link="right_link5" />
        <child link="right_link6" />
        <dynamics damping="0.7" />
    </joint>
    <joint name="right_joint6" type="revolute">
        <limit effort="1000.0" lower="-1.2217304763960306" upper="1.5707963267948966" velocity="9.42477796076938" />
        <origin rpy="-1.5707963267948966 0 0" xyz="0.203 0 0" />
        <axis xyz="0 1 0" />
        <parent link="right_link6" />
        <child link="right_link7" />
        <dynamics damping="0.7" />
    </joint>
    <joint name="right_joint7" type="revolute">
        <limit effort="1000.0" lower="-1.5707963267948966" upper="1.5707963267948966" velocity="9.42477796076938" />
        <origin rpy="0.0 0 0" xyz="0.0 0 0" />
        <axis xyz="0 0 1" />
        <parent link="right_link7" />
        <child link="right_link8" />
        <dynamics damping="0.7" />
    </joint>
    <joint name="right_hand_joint1" type="revolute">
        <limit effort="1000.0" lower="-1.5707963267948966" upper="1.5707963267948966" velocity="9.42477796076938" />
        <origin rpy="0 0 0" xyz="0.0865 0.0265 0.0240" />
        <axis xyz="0 0 1" />
        <parent link="right_link8" />
        <child link="right_hand1" />
        <dynamics damping="0.7" />
    </joint>
    <joint name="right_hand_joint2" type="revolute">
        <limit effort="1000.0" lower="-1.5707963267948966" upper="1.5707963267948966" velocity="9.42477796076938" />
        <origin rpy="0 0 0" xyz="0.0865 0 0.024" />
        <axis xyz="0 0 1" />
        <parent link="right_link8" />
        <child link="right_hand2" />
        <dynamics damping="0.7" />
    </joint>
    <!-- Grasping frame -->
    <link name="rightgrasping_frame" />
    <joint name="rightgrasping_frame_joint" type="fixed">
        <parent link="right_link8" />
        <child link="rightgrasping_frame" />
        <origin rpy="0 0 0" xyz="0.1565 0.0265 0.0240" />
    </joint>
    <link name="right_marker" />
    <joint name="camera_marker_joint" type="fixed">
        <parent link="right_link8" />
        <child link="right_marker" />
        <origin rpy="3.141592653589793 -1.5707963267948966 0.0" xyz="0 -0.015 0.05" />
    </joint>
    <!-- ///////////////////   Transmissions for ROS Control /////////////////// -->
    <transmission name="right_tran1">
        <type>transmission_interface/SimpleTransmission</type>
        <joint name="right_joint1">
            <hardwareInterface>hardware_interface/PositionJointInterface</hardwareInterface>
        </joint>
        <actuator name="right_motor1">
            <hardwareInterface>hardware_interface/PositionJointInterface</hardwareInterface>
            <mechanicalReduction>1</mechanicalReduction>
        </actuator>
    </transmission>
    <transmission name="right_tran2">
        <type>transmission_interface/SimpleTransmission</type>
        <joint name="right_joint2">
            <hardwareInterface>hardware_interface/PositionJointInterface</hardwareInterface>
        </joint>
        <actuator name="right_motor2">
            <hardwareInterface>hardware_interface/PositionJointInterface</hardwareInterface>
            <mechanicalReduction>1</mechanicalReduction>
        </actuator>
    </transmission>
    <transmission name="right_tran3">
        <type>transmission_interface/SimpleTransmission</type>
        <joint name="right_joint3">
            <hardwareInterface>hardware_interface/PositionJointInterface</hardwareInterface>
        </joint>
        <actuator name="right_motor3">
            <hardwareInterface>hardware_interface/PositionJointInterface</hardwareInterface>
            <mechanicalReduction>1</mechanicalReduction>
        </actuator>
    </transmission>
    <transmission name="right_tran4">
        <type>transmission_interface/SimpleTransmission</type>
        <joint name="right_joint4">
            <hardwareInterface>hardware_interface/PositionJointInterface</hardwareInterface>
        </joint>
        <actuator name="right_motor4">
            <hardwareInterface>hardware_interface/PositionJointInterface</hardwareInterface>
            <mechanicalReduction>1</mechanicalReduction>
        </actuator>
    </transmission>
    <transmission name="right_tran5">
        <type>transmission_interface/SimpleTransmission</type>
        <joint name="right_joint5">
            <hardwareInterface>hardware_interface/PositionJointInterface</hardwareInterface>
        </joint>
        <actuator name="right_motor5">
            <hardwareInterface>hardware_interface/PositionJointInterface</hardwareInterface>
            <mechanicalReduction>1</mechanicalReduction>
        </actuator>
    </transmission>
    <transmission name="right_tran6">
        <type>transmission_interface/SimpleTransmission</type>
        <joint name="right_joint6">
            <hardwareInterface>hardware_interface/PositionJointInterface</hardwareInterface>
        </joint>
        <actuator name="right_motor6">
            <hardwareInterface>hardware_interface/PositionJointInterface</hardwareInterface>
            <mechanicalReduction>1</mechanicalReduction>
        </actuator>
    </transmission>
    <transmission name="right_tran7">
        <type>transmission_interface/SimpleTransmission</type>
        <joint name="right_joint7">
            <hardwareInterface>hardware_interface/PositionJointInterface</hardwareInterface>
        </joint>
        <actuator name="right_motor7">
            <hardwareInterface>hardware_interface/PositionJointInterface</hardwareInterface>
            <mechanicalReduction>1</mechanicalReduction>
        </actuator>
    </transmission>
    <transmission name="right_tran8">
        <type>transmission_interface/SimpleTransmission</type>
        <joint name="right_hand_joint1">
            <hardwareInterface>hardware_interface/PositionJointInterface</hardwareInterface>
        </joint>
        <actuator name="right_motor8">
            <hardwareInterface>hardware_interface/PositionJointInterface</hardwareInterface>
            <mechanicalReduction>1</mechanicalReduction>
        </actuator>
    </transmission>
    <transmission name="right_tran9">
        <type>transmission_interface/SimpleTransmission</type>
        <joint name="right_hand_joint2">
            <hardwareInterface>hardware_interface/PositionJointInterface</hardwareInterface>
        </joint>
        <actuator name="right_motor8">
            <hardwareInterface>hardware_interface/PositionJointInterface</hardwareInterface>
            <mechanicalReduction>1</mechanicalReduction>
        </actuator>
    </transmission>
    <link name="left_link1">
        <visual>
            <geometry>
                <mesh filename="package://bmirobot_description/modle/stl_V5/baselink.dae" />
            </geometry>
            <origin rpy="0 0 0" xyz="0 0 0" />
            <material name="red" />
        </visual>
        <collision>
            <geometry>
                <mesh filename="package://bmirobot_description/modle/stl_V5/baselink.dae" />
            </geometry>
            <origin rpy="0 0 0" xyz="0 0 0" />
        </collision>
        <inertial>
            <origin rpy="0 0 0" xyz="0 0 1" />
            <mass value="1" />
            <inertia ixx="1.0" ixy="0.0" ixz="0.0" iyy="1.0" iyz="0.0" izz="1.0" />
        </inertial>
    </link>
    <link name="left_link2">
        <visual>
            <geometry>
                <mesh filename="package://bmirobot_description/modle/stl_V5/link1.dae" />
            </geometry>
            <origin rpy="0 0 0" xyz="0 0 0" />
            <material name="white" />
        </visual>
        <collision>
            <geometry>
                <mesh filename="package://bmirobot_description/modle/stl_V5/link1.dae" />
            </geometry>
            <origin rpy="0 0 0" xyz="0 0 0" />
        </collision>
        <inertial>
            <origin rpy="0 0 0" xyz="0 0 1" />
            <mass value="1" />
            <inertia ixx="1.0" ixy="0.0" ixz="0.0" iyy="1.0" iyz="0.0" izz="1.0" />
        </inertial>
    </link>
    <link name="left_link3">
        <visual>
            <geometry>
                <mesh filename="package://bmirobot_description/modle/stl_V5/link2.dae" />
            </geometry>
            <origin rpy="0 0 0" xyz="0 0 0" />
            <material name="blue" />
        </visual>
        <collision>
            <geometry>
                <mesh filename="package://bmirobot_description/modle/stl_V5/link2.dae" />
            </geometry>
            <origin rpy="0 0 0" xyz="0 0 0" />
        </collision>
        <inertial>
            <origin rpy="0 0 0" xyz="0 0 1" />
            <mass value="1" />
            <inertia ixx="1.0" ixy="0.0" ixz="0.0" iyy="1.0" iyz="0.0" izz="1.0" />
        </inertial>
    </link>
    <link name="left_link4">
        <visual>
            <geometry>
                <mesh filename="package://bmirobot_description/modle/stl_V5/link3.dae" />
            </geometry>
            <origin rpy="0 0 0" xyz="0 0 0" />
            <material name="orange" />
        </visual>
        <collision>
            <geometry>
                <mesh filename="package://bmirobot_description/modle/stl_V5/link3.dae" />
            </geometry>
            <origin rpy="0 0 0" xyz="0 0 0" />
        </collision>
        <inertial>
            <origin rpy="0 0 0" xyz="0 0 1" />
            <mass value="1" />
            <inertia ixx="1.0" ixy="0.0" ixz="0.0" iyy="1.0" iyz="0.0" izz="1.0" />
        </inertial>
    </link>
    <link name="left_link5">
        <visual>
            <geometry>
                <mesh filename="package://bmirobot_description/modle/stl_V5/link4.dae" />
            </geometry>
            <origin rpy="0 0 0" xyz="0 0 0" />
            <material name="blue" />
        </visual>
        <collision>
            <geometry>
                <mesh filename="package://bmirobot_description/modle/stl_V5/link4.dae" />
            </geometry>
            <origin rpy="0 0 0" xyz="0 0 0" />
        </collision>
        <inertial>
            <origin rpy="0 0 0" xyz="0 0 1" />
            <mass value="1" />
            <inertia ixx="1.0" ixy="0.0" ixz="0.0" iyy="1.0" iyz="0.0" izz="1.0" />
        </inertial>
    </link>
    <link name="left_link6">
        <visual>
            <geometry>
                <mesh filename="package://bmirobot_description/modle/stl_V5/link5.dae" />
            </geometry>
            <origin rpy="0 0 0" xyz="0 0 0" />
            <material name="orange" />
        </visual>
        <collision>
            <geometry>
                <mesh filename="package://bmirobot_description/modle/stl_V5/link5.dae" />
            </geometry>
            <origin rpy="0 0 0" xyz="0 0 0" />
        </collision>
        <inertial>
            <origin rpy="0 0 0" xyz="0 0 1" />
            <mass value="1" />
            <inertia ixx="1.0" ixy="0.0" ixz="0.0" iyy="1.0" iyz="0.0" izz="1.0" />
        </inertial>
    </link>
    <link name="left_link7">
        <visual>
            <geometry>
                <mesh filename="package://bmirobot_description/modle/stl_V5/link6.dae" />
            </geometry>
            <origin rpy="0 0 0" xyz="0 0 0" />
            <material name="blue" />
        </visual>
        <collision>
            <geometry>
                <mesh filename="package://bmirobot_description/modle/stl_V5/link6.dae" />
            </geometry>
            <origin rpy="0 0 0" xyz="0 0 0" />
        </collision>
        <inertial>
            <origin rpy="0 0 0" xyz="0 0 1" />
            <mass value="1" />
            <inertia ixx="1.0" ixy="0.0" ixz="0.0" iyy="1.0" iyz="0.0" izz="1.0" />
        </inertial>
    </link>
    <link name="left_link8">
        <visual>
            <geometry>
                <mesh filename="package://bmirobot_description/modle/stl_V5/link7.dae" />
            </geometry>
            <origin rpy="0 0 0" xyz="0 0 0" />
            <material name="red" />
        </visual>
        <collision>
            <geometry>
                <mesh filename="package://bmirobot_description/modle/stl_V5/link7.dae" />
            </geometry>
            <origin rpy="0 0 0" xyz="0 0 0" />
        </collision>
        <inertial>
            <origin rpy="0 0 0" xyz="0 0 1" />
            <mass value="1" />
            <inertia ixx="1.0" ixy="0.0" ixz="0.0" iyy="1.0" iyz="0.0" izz="1.0" />
        </inertial>
    </link>
    <link name="left_hand1">
        <visual>
            <geometry>
                <mesh filename="package://bmirobot_description/modle/stl_V5/hand-1.dae" />
            </geometry>
            <origin rpy="0 0 0" xyz="0 0 0" />
            <material name="white" />
        </visual>
        <collision>
            <geometry>
                <mesh filename="package://bmirobot_description/modle/stl_V5/hand-1.dae" />
            </geometry>
            <origin rpy="0 0 0" xyz="0 0 0" />
        </collision>
        <inertial>
            <origin rpy="0 0 0" xyz="0 0 1" />
            <mass value="1" />
            <inertia ixx="1.0" ixy="0.0" ixz="0.0" iyy="1.0" iyz="0.0" izz="1.0" />
        </inertial>
    </link>
    <link name="left_hand2">
        <visual>
            <geometry>
                <mesh filename="package://bmirobot_description/modle/stl_V5/hand-2.dae" />
            </geometry>
            <origin rpy="0 0 0" xyz="0 0 0" />
            <material name="white" />
        </visual>
        <collision>
            <geometry>
                <mesh filename="package://bmirobot_description/modle/stl_V5/hand-2.dae" />
            </geometry>
            <origin rpy="0 0 0" xyz="0 0 0" />
        </collision>
        <inertial>
            <origin rpy="0 0 0" xyz="0 0 1" />
            <mass value="1" />
            <inertia ixx="1.0" ixy="0.0" ixz="0.0" iyy="1.0" iyz="0.0" izz="1.0" />
        </inertial>
    </link>
    <joint name="left_joint1" type="revolute">
        <limit effort="1000.0" lower="-1.5707963267948966" upper="3.141592653589793" velocity="9.42477796076938" />
        <origin rpy="0 0 0" xyz="0.081 0 0" />
        <axis xyz="1 0 0" />
        <parent link="left_link1" />
        <child link="left_link2" />
        <dynamics damping="0.7" />
    </joint>
    <joint name="left_joint2" type="revolute">
        <limit effort="1000.0" lower="-3.141592653589793" upper="0.17453292519943295" velocity="9.42477796076938" />
        <origin rpy="0 1.5707963267948966 0" xyz="0.040 0 0" />
        <axis xyz="0 1 0" />
        <parent link="left_link2" />
        <child link="left_link3" />
        <dynamics damping="0.7" />
    </joint>
    <joint name="left_joint3" type="revolute">
        <limit effort="1000.0" lower="-2.199114857512855" upper="2.199114857512855" velocity="9.42477796076938" />
        <origin rpy="1.5707963267948966 0 0" xyz="0.0555 0 0" />
        <axis xyz="1 0 0" />
        <parent link="left_link3" />
        <child link="left_link4" />
        <dynamics damping="0.7" />
    </joint>
    <joint name="left_joint4" type="revolute">
        <limit effort="1000.0" lower="-0.8726646259971648" upper="2.0943951023931953" velocity="9.42477796076938" />
        <origin rpy="0 -1.5707963267948966 0" xyz="0.1945 0 0" />
        <axis xyz="0 1 0" />
        <parent link="left_link4" />
        <child link="left_link5" />
        <dynamics damping="0.7" />
    </joint>
    <joint name="left_joint5" type="revolute">
        <limit effort="1000.0" lower="-3.141592653589793" upper="1.7453292519943295" velocity="9.42477796076938" />
        <origin rpy="1.5707963267948966 0 0" xyz="0.037 0 0.000" />
        <axis xyz="1 0 0" />
        <parent link="left_link5" />
        <child link="left_link6" />
        <dynamics damping="0.7" />
    </joint>
    <joint name="left_joint6" type="revolute">
        <limit effort="1000.0" lower="-1.2217304763960306" upper="1.5707963267948966" velocity="9.42477796076938" />
        <origin rpy="-1.5707963267948966 0 0" xyz="0.203 0 0" />
        <axis xyz="0 1 0" />
        <parent link="left_link6" />
        <child link="left_link7" />
        <dynamics damping="0.7" />
    </joint>
    <joint name="left_joint7" type="revolute">
        <limit effort="1000.0" lower="-1.5707963267948966" upper="1.5707963267948966" velocity="9.42477796076938" />
        <origin rpy="0.0 0 0" xyz="0.0 0 0" />
        <axis xyz="0 0 1" />
        <parent link="left_link7" />
        <child link="left_link8" />
        <dynamics damping="0.7" />
    </joint>
    <joint name="left_hand_joint1" type="revolute">
        <limit effort="1000.0" lower="0.0" upper="0.7853981633974483" velocity="9.42477796076938" />
        <origin rpy="0 0 0" xyz="0.0865 0.0265 0.0240" />
        <axis xyz="0 0 1" />
        <parent link="left_link8" />
        <child link="left_hand1" />
        <dynamics damping="0.7" />
    </joint>
    <joint name="left_hand_joint2" type="revolute">
        <limit effort="1000.0" lower="-0.7853981633974483" upper="0.0" velocity="9.42477796076938" />
        <origin rpy="0 0 0" xyz="0.0865 0 0.024" />
        <axis xyz="0 0 1" />
        <parent link="left_link8" />
        <child link="left_hand2" />
        <dynamics damping="0.7" />
    </joint>
    <!-- Grasping frame -->
    <link name="leftgrasping_frame" />
    <joint name="leftgrasping_frame_joint" type="fixed">
        <parent link="left_link8" />
        <child link="leftgrasping_frame" />
        <origin rpy="0 0 0" xyz="0.1565 0.0265 0.0240" />
    </joint>
    <!-- ///////////////////   Transmissions for ROS Control /////////////////// -->
    <transmission name="left_tran1">
        <type>transmission_interface/SimpleTransmission</type>
        <joint name="left_joint1">
            <hardwareInterface>hardware_interface/PositionJointInterface</hardwareInterface>
        </joint>
        <actuator name="left_motor1">
            <hardwareInterface>hardware_interface/PositionJointInterface</hardwareInterface>
            <mechanicalReduction>1</mechanicalReduction>
        </actuator>
    </transmission>
    <transmission name="left_tran2">
        <type>transmission_interface/SimpleTransmission</type>
        <joint name="left_joint2">
            <hardwareInterface>hardware_interface/PositionJointInterface</hardwareInterface>
        </joint>
        <actuator name="left_motor2">
            <hardwareInterface>hardware_interface/PositionJointInterface</hardwareInterface>
            <mechanicalReduction>1</mechanicalReduction>
        </actuator>
    </transmission>
    <transmission name="left_tran3">
        <type>transmission_interface/SimpleTransmission</type>
        <joint name="left_joint3">
            <hardwareInterface>hardware_interface/PositionJointInterface</hardwareInterface>
        </joint>
        <actuator name="left_motor3">
            <hardwareInterface>hardware_interface/PositionJointInterface</hardwareInterface>
            <mechanicalReduction>1</mechanicalReduction>
        </actuator>
    </transmission>
    <transmission name="left_tran4">
        <type>transmission_interface/SimpleTransmission</type>
        <joint name="left_joint4">
            <hardwareInterface>hardware_interface/PositionJointInterface</hardwareInterface>
        </joint>
        <actuator name="left_motor4">
            <hardwareInterface>hardware_interface/PositionJointInterface</hardwareInterface>
            <mechanicalReduction>1</mechanicalReduction>
        </actuator>
    </transmission>
    <transmission name="left_tran5">
        <type>transmission_interface/SimpleTransmission</type>
        <joint name="left_joint5">
            <hardwareInterface>hardware_interface/PositionJointInterface</hardwareInterface>
        </joint>
        <actuator name="left_motor5">
            <hardwareInterface>hardware_interface/PositionJointInterface</hardwareInterface>
            <mechanicalReduction>1</mechanicalReduction>
        </actuator>
    </transmission>
    <transmission name="left_tran6">
        <type>transmission_interface/SimpleTransmission</type>
        <joint name="left_joint6">
            <hardwareInterface>hardware_interface/PositionJointInterface</hardwareInterface>
        </joint>
        <actuator name="left_motor6">
            <hardwareInterface>hardware_interface/PositionJointInterface</hardwareInterface>
            <mechanicalReduction>1</mechanicalReduction>
        </actuator>
    </transmission>
    <transmission name="left_tran7">
        <type>transmission_interface/SimpleTransmission</type>
        <joint name="left_joint7">
            <hardwareInterface>hardware_interface/PositionJointInterface</hardwareInterface>
        </joint>
        <actuator name="left_motor7">
            <hardwareInterface>hardware_interface/PositionJointInterface</hardwareInterface>
            <mechanicalReduction>1</mechanicalReduction>
        </actuator>
    </transmission>
    <transmission name="left_tran8">
        <type>transmission_interface/SimpleTransmission</type>
        <joint name="left_hand_joint1">
            <hardwareInterface>hardware_interface/PositionJointInterface</hardwareInterface>
        </joint>
        <actuator name="left_motor8">
            <hardwareInterface>hardware_interface/PositionJointInterface</hardwareInterface>
            <mechanicalReduction>1</mechanicalReduction>
        </actuator>
    </transmission>
    <transmission name="left_tran9">
        <type>transmission_interface/SimpleTransmission</type>
        <joint name="left_hand_joint2">
            <hardwareInterface>hardware_interface/PositionJointInterface</hardwareInterface>
        </joint>
        <actuator name="left_motor8">
            <hardwareInterface>hardware_interface/PositionJointInterface</hardwareInterface>
            <mechanicalReduction>1</mechanicalReduction>
        </actuator>
    </transmission>
    <gazebo>
        <plugin name="gazebo_ros_control">
            <robotNamespace>/</robotNamespace>
        </plugin>
    </gazebo>
</robot>

